INFO:werkzeug: * Running on http://0.0.0.0:5000/ (Press CTRL+C to quit)
INFO:werkzeug: * Restarting with stat
WARNING:werkzeug: * Debugger is active!
INFO:werkzeug: * Debugger PIN: 287-863-292
INFO:werkzeug:10.10.72.124 - - [21/Feb/2022 15:02:06] "[37mGET / HTTP/1.1[0m" 200 -
INFO:werkzeug:10.10.72.124 - - [21/Feb/2022 15:02:08] "[37mGET /static/css/custom.css HTTP/1.1[0m" 200 -
INFO:werkzeug:10.10.72.124 - - [21/Feb/2022 15:02:08] "[37mGET /static/css/theme.css HTTP/1.1[0m" 200 -
INFO:werkzeug:10.10.72.124 - - [21/Feb/2022 15:02:10] "[37mGET /static/js/new_ajax_helper.js HTTP/1.1[0m" 200 -
INFO:werkzeug:10.10.72.124 - - [21/Feb/2022 15:02:16] "[37mGET /static/js/custom.js HTTP/1.1[0m" 200 -
INFO:werkzeug:10.10.72.124 - - [21/Feb/2022 15:02:44] "[33mGET /favicon.ico HTTP/1.1[0m" 404 -
INFO:flask_app:[{'userid': 1, 'email': 'admin@admin', 'name': 'admin', 'permission': 'admin', 'password': 'admin'}]
INFO:werkzeug:10.10.72.124 - - [21/Feb/2022 15:02:56] "[32mPOST / HTTP/1.1[0m" 302 -
INFO:werkzeug:10.10.72.124 - - [21/Feb/2022 15:02:56] "[37mGET /dashboard HTTP/1.1[0m" 200 -
INFO:werkzeug:10.10.72.124 - - [21/Feb/2022 15:02:57] "[37mGET /static/js/dashboard.js HTTP/1.1[0m" 200 -
INFO:werkzeug:10.10.72.124 - - [21/Feb/2022 15:02:57] "[37mGET /static/js/mapping.js HTTP/1.1[0m" 200 -
INFO:flask_app:LOADING CAMERA
INFO:root:CAMERA INTERFACE: Started Camera Thread
INFO:flask_app:LOADING THE ROBOT
INFO:flask_app:BRICKPIINTERFACE: Starting thermal sensor thread
INFO:flask_app:LOADING THE SOUND
INFO:flask_app:ULTRASONIC: get_sensor error: Invalid sensor data
INFO:werkzeug:10.10.72.124 - - [21/Feb/2022 15:03:07] "[37mPOST /robotload HTTP/1.1[0m" 200 -
INFO:flask_app:READING CAMERA
INFO:werkzeug:10.10.72.124 - - [21/Feb/2022 15:03:08] "[37mGET /videofeed HTTP/1.1[0m" 200 -
INFO:flask_app:ULTRASONIC: get_sensor error: Invalid sensor data
INFO:werkzeug:10.10.72.124 - - [21/Feb/2022 15:03:30] "[37mPOST /reconfig_IMU HTTP/1.1[0m" 200 -
INFO:flask_app:Move around the robot to calibrate the Compass Sensor...
INFO:flask_app:ULTRASONIC: get_sensor error: Invalid sensor data
INFO:flask_app:IMU Acceleration: [Errno 5] Input/output error
INFO:flask_app:IMU Calibration Error: [Errno 5] Input/output error
INFO:flask_app:IMU Orientation: 'int' object is not iterable
INFO:werkzeug:10.10.72.124 - - [21/Feb/2022 15:03:37] "[37mPOST /sensors HTTP/1.1[0m" 200 -
INFO:flask_app:Calibrating IMU. Status: 0 Time: 1
INFO:flask_app:Calibrating IMU. Status: 0 Time: 2
INFO:flask_app:Calibrating IMU. Status: 0 Time: 3
INFO:flask_app:IMU Calibration Error: [Errno 5] Input/output error
INFO:flask_app:IMU Calibration Error: [Errno 5] Input/output error
INFO:flask_app:Calibrating IMU. Status: 0 Time: 4
INFO:flask_app:Calibrating IMU. Status: 0 Time: 5
INFO:flask_app:Calibrating IMU. Status: 0 Time: 6
INFO:flask_app:Calibrating IMU. Status: 0 Time: 7
INFO:flask_app:Calibrating IMU. Status: 0 Time: 8
INFO:flask_app:Calibrating IMU. Status: 0 Time: 9
INFO:flask_app:Calibration unsuccessful. Please rotate in 3 dimensions
INFO:werkzeug:10.10.72.124 - - [21/Feb/2022 15:03:47] "[37mPOST /compass HTTP/1.1[0m" 200 -
INFO:werkzeug:10.10.72.124 - - [21/Feb/2022 15:10:06] "[37mGET /dashboard HTTP/1.1[0m" 200 -
INFO:flask_app:READING CAMERA
INFO:werkzeug:10.10.72.124 - - [21/Feb/2022 15:10:07] "[37mGET /videofeed HTTP/1.1[0m" 200 -
INFO:werkzeug:10.10.72.124 - - [21/Feb/2022 15:10:20] "[37mGET /dashboard HTTP/1.1[0m" 200 -
INFO:flask_app:READING CAMERA
INFO:werkzeug:10.10.72.124 - - [21/Feb/2022 15:10:20] "[37mGET /videofeed HTTP/1.1[0m" 200 -
INFO:werkzeug:127.0.0.1 - - [23/Feb/2022 12:27:10] "[37mGET / HTTP/1.1[0m" 200 -
INFO:werkzeug:127.0.0.1 - - [23/Feb/2022 12:27:10] "[37mGET /static/css/theme.css HTTP/1.1[0m" 200 -
INFO:werkzeug:127.0.0.1 - - [23/Feb/2022 12:27:10] "[37mGET /static/css/custom.css HTTP/1.1[0m" 200 -
INFO:werkzeug:127.0.0.1 - - [23/Feb/2022 12:27:10] "[37mGET /static/js/new_ajax_helper.js HTTP/1.1[0m" 200 -
INFO:werkzeug:127.0.0.1 - - [23/Feb/2022 12:27:10] "[37mGET /static/js/custom.js HTTP/1.1[0m" 200 -
INFO:werkzeug:127.0.0.1 - - [23/Feb/2022 12:27:11] "[33mGET /favicon.ico HTTP/1.1[0m" 404 -
INFO:werkzeug: * Detected change in '/home/pi/Desktop/brickpi2022/flask_app.py', reloading
INFO:werkzeug: * Restarting with stat
INFO:werkzeug:127.0.0.1 - - [23/Feb/2022 13:54:13] "[37mGET / HTTP/1.1[0m" 200 -
INFO:flask_app:[{'userid': 1, 'password': 'admin', 'permission': 'admin', 'name': 'admin', 'email': 'admin@admin'}]
INFO:werkzeug:127.0.0.1 - - [23/Feb/2022 13:54:22] "[32mPOST / HTTP/1.1[0m" 302 -
INFO:werkzeug:127.0.0.1 - - [23/Feb/2022 13:54:22] "[37mGET /dashboard HTTP/1.1[0m" 200 -
INFO:werkzeug:127.0.0.1 - - [23/Feb/2022 13:54:23] "[37mGET /static/js/mapping.js HTTP/1.1[0m" 200 -
INFO:werkzeug:127.0.0.1 - - [23/Feb/2022 13:54:23] "[37mGET /static/js/dashboard.js HTTP/1.1[0m" 200 -
INFO:werkzeug:127.0.0.1 - - [23/Feb/2022 13:54:51] "[37mGET /dashboard HTTP/1.1[0m" 200 -
INFO:werkzeug:127.0.0.1 - - [23/Feb/2022 13:54:57] "[37mGET /dashboard HTTP/1.1[0m" 200 -
INFO:flask_app:SHUT DOWN EVERYTHING
INFO:werkzeug:127.0.0.1 - - [23/Feb/2022 13:55:01] "[32mGET /logout HTTP/1.1[0m" 302 -
INFO:werkzeug:127.0.0.1 - - [23/Feb/2022 13:55:01] "[37mGET / HTTP/1.1[0m" 200 -
INFO:flask_app:[{'userid': 1, 'password': 'admin', 'permission': 'admin', 'name': 'admin', 'email': 'admin@admin'}]
INFO:werkzeug:127.0.0.1 - - [23/Feb/2022 13:55:09] "[32mPOST / HTTP/1.1[0m" 302 -
INFO:werkzeug:127.0.0.1 - - [23/Feb/2022 13:55:09] "[37mGET /dashboard HTTP/1.1[0m" 200 -
INFO:werkzeug:127.0.0.1 - - [23/Feb/2022 13:55:50] "[37mGET /dashboard HTTP/1.1[0m" 200 -
INFO:werkzeug:127.0.0.1 - - [23/Feb/2022 13:55:50] "[37mGET /static/js/brick_pi_2022_dashboard.js HTTP/1.1[0m" 200 -
INFO:werkzeug:127.0.0.1 - - [23/Feb/2022 13:55:52] "[35m[1mPOST /process_movement HTTP/1.1[0m" 500 -
INFO:werkzeug:127.0.0.1 - - [23/Feb/2022 13:55:52] "[35m[1mPOST /process_movement HTTP/1.1[0m" 500 -
ERROR:werkzeug:Error on request:
Traceback (most recent call last):
  File "/home/pi/.local/lib/python3.5/site-packages/werkzeug/serving.py", line 323, in run_wsgi
    execute(self.server.app)
  File "/home/pi/.local/lib/python3.5/site-packages/werkzeug/serving.py", line 312, in execute
    application_iter = app(environ, start_response)
  File "/home/pi/.local/lib/python3.5/site-packages/flask/app.py", line 2464, in __call__
    return self.wsgi_app(environ, start_response)
  File "/home/pi/.local/lib/python3.5/site-packages/flask/app.py", line 2450, in wsgi_app
    response = self.handle_exception(e)
  File "/home/pi/.local/lib/python3.5/site-packages/flask/app.py", line 1867, in handle_exception
    reraise(exc_type, exc_value, tb)
  File "/home/pi/.local/lib/python3.5/site-packages/flask/_compat.py", line 39, in reraise
    raise value
  File "/home/pi/.local/lib/python3.5/site-packages/flask/app.py", line 2447, in wsgi_app
    response = self.full_dispatch_request()
  File "/home/pi/.local/lib/python3.5/site-packages/flask/app.py", line 1952, in full_dispatch_request
    rv = self.handle_user_exception(e)
  File "/home/pi/.local/lib/python3.5/site-packages/flask/app.py", line 1821, in handle_user_exception
    reraise(exc_type, exc_value, tb)
  File "/home/pi/.local/lib/python3.5/site-packages/flask/_compat.py", line 39, in reraise
    raise value
  File "/home/pi/.local/lib/python3.5/site-packages/flask/app.py", line 1950, in full_dispatch_request
    rv = self.dispatch_request()
  File "/home/pi/.local/lib/python3.5/site-packages/flask/app.py", line 1936, in dispatch_request
    return self.view_functions[rule.endpoint](**req.view_args)
  File "/home/pi/Desktop/brickpi2022/flask_app.py", line 105, in process_movement
    data = request.form.get()
TypeError: get() missing 1 required positional argument: 'key'
ERROR:werkzeug:Error on request:
Traceback (most recent call last):
  File "/home/pi/.local/lib/python3.5/site-packages/werkzeug/serving.py", line 323, in run_wsgi
    execute(self.server.app)
  File "/home/pi/.local/lib/python3.5/site-packages/werkzeug/serving.py", line 312, in execute
    application_iter = app(environ, start_response)
  File "/home/pi/.local/lib/python3.5/site-packages/flask/app.py", line 2464, in __call__
    return self.wsgi_app(environ, start_response)
  File "/home/pi/.local/lib/python3.5/site-packages/flask/app.py", line 2450, in wsgi_app
    response = self.handle_exception(e)
  File "/home/pi/.local/lib/python3.5/site-packages/flask/app.py", line 1867, in handle_exception
    reraise(exc_type, exc_value, tb)
  File "/home/pi/.local/lib/python3.5/site-packages/flask/_compat.py", line 39, in reraise
    raise value
  File "/home/pi/.local/lib/python3.5/site-packages/flask/app.py", line 2447, in wsgi_app
    response = self.full_dispatch_request()
  File "/home/pi/.local/lib/python3.5/site-packages/flask/app.py", line 1952, in full_dispatch_request
    rv = self.handle_user_exception(e)
  File "/home/pi/.local/lib/python3.5/site-packages/flask/app.py", line 1821, in handle_user_exception
    reraise(exc_type, exc_value, tb)
  File "/home/pi/.local/lib/python3.5/site-packages/flask/_compat.py", line 39, in reraise
    raise value
  File "/home/pi/.local/lib/python3.5/site-packages/flask/app.py", line 1950, in full_dispatch_request
    rv = self.dispatch_request()
  File "/home/pi/.local/lib/python3.5/site-packages/flask/app.py", line 1936, in dispatch_request
    return self.view_functions[rule.endpoint](**req.view_args)
  File "/home/pi/Desktop/brickpi2022/flask_app.py", line 105, in process_movement
    data = request.form.get()
TypeError: get() missing 1 required positional argument: 'key'
INFO:werkzeug:127.0.0.1 - - [23/Feb/2022 13:56:01] "[35m[1mPOST /process_movement HTTP/1.1[0m" 500 -
ERROR:werkzeug:Error on request:
Traceback (most recent call last):
  File "/home/pi/.local/lib/python3.5/site-packages/werkzeug/serving.py", line 323, in run_wsgi
    execute(self.server.app)
  File "/home/pi/.local/lib/python3.5/site-packages/werkzeug/serving.py", line 312, in execute
    application_iter = app(environ, start_response)
  File "/home/pi/.local/lib/python3.5/site-packages/flask/app.py", line 2464, in __call__
    return self.wsgi_app(environ, start_response)
  File "/home/pi/.local/lib/python3.5/site-packages/flask/app.py", line 2450, in wsgi_app
    response = self.handle_exception(e)
  File "/home/pi/.local/lib/python3.5/site-packages/flask/app.py", line 1867, in handle_exception
    reraise(exc_type, exc_value, tb)
  File "/home/pi/.local/lib/python3.5/site-packages/flask/_compat.py", line 39, in reraise
    raise value
  File "/home/pi/.local/lib/python3.5/site-packages/flask/app.py", line 2447, in wsgi_app
    response = self.full_dispatch_request()
  File "/home/pi/.local/lib/python3.5/site-packages/flask/app.py", line 1952, in full_dispatch_request
    rv = self.handle_user_exception(e)
  File "/home/pi/.local/lib/python3.5/site-packages/flask/app.py", line 1821, in handle_user_exception
    reraise(exc_type, exc_value, tb)
  File "/home/pi/.local/lib/python3.5/site-packages/flask/_compat.py", line 39, in reraise
    raise value
  File "/home/pi/.local/lib/python3.5/site-packages/flask/app.py", line 1950, in full_dispatch_request
    rv = self.dispatch_request()
  File "/home/pi/.local/lib/python3.5/site-packages/flask/app.py", line 1936, in dispatch_request
    return self.view_functions[rule.endpoint](**req.view_args)
  File "/home/pi/Desktop/brickpi2022/flask_app.py", line 105, in process_movement
    data = request.form.get()
TypeError: get() missing 1 required positional argument: 'key'
INFO:werkzeug:127.0.0.1 - - [23/Feb/2022 13:56:01] "[35m[1mPOST /process_movement HTTP/1.1[0m" 500 -
ERROR:werkzeug:Error on request:
Traceback (most recent call last):
  File "/home/pi/.local/lib/python3.5/site-packages/werkzeug/serving.py", line 323, in run_wsgi
    execute(self.server.app)
  File "/home/pi/.local/lib/python3.5/site-packages/werkzeug/serving.py", line 312, in execute
    application_iter = app(environ, start_response)
  File "/home/pi/.local/lib/python3.5/site-packages/flask/app.py", line 2464, in __call__
    return self.wsgi_app(environ, start_response)
  File "/home/pi/.local/lib/python3.5/site-packages/flask/app.py", line 2450, in wsgi_app
    response = self.handle_exception(e)
  File "/home/pi/.local/lib/python3.5/site-packages/flask/app.py", line 1867, in handle_exception
    reraise(exc_type, exc_value, tb)
  File "/home/pi/.local/lib/python3.5/site-packages/flask/_compat.py", line 39, in reraise
    raise value
  File "/home/pi/.local/lib/python3.5/site-packages/flask/app.py", line 2447, in wsgi_app
    response = self.full_dispatch_request()
  File "/home/pi/.local/lib/python3.5/site-packages/flask/app.py", line 1952, in full_dispatch_request
    rv = self.handle_user_exception(e)
  File "/home/pi/.local/lib/python3.5/site-packages/flask/app.py", line 1821, in handle_user_exception
    reraise(exc_type, exc_value, tb)
  File "/home/pi/.local/lib/python3.5/site-packages/flask/_compat.py", line 39, in reraise
    raise value
  File "/home/pi/.local/lib/python3.5/site-packages/flask/app.py", line 1950, in full_dispatch_request
    rv = self.dispatch_request()
  File "/home/pi/.local/lib/python3.5/site-packages/flask/app.py", line 1936, in dispatch_request
    return self.view_functions[rule.endpoint](**req.view_args)
  File "/home/pi/Desktop/brickpi2022/flask_app.py", line 105, in process_movement
    data = request.form.get()
TypeError: get() missing 1 required positional argument: 'key'
INFO:werkzeug:127.0.0.1 - - [23/Feb/2022 13:56:01] "[35m[1mPOST /process_movement HTTP/1.1[0m" 500 -
ERROR:werkzeug:Error on request:
Traceback (most recent call last):
  File "/home/pi/.local/lib/python3.5/site-packages/werkzeug/serving.py", line 323, in run_wsgi
    execute(self.server.app)
  File "/home/pi/.local/lib/python3.5/site-packages/werkzeug/serving.py", line 312, in execute
    application_iter = app(environ, start_response)
  File "/home/pi/.local/lib/python3.5/site-packages/flask/app.py", line 2464, in __call__
    return self.wsgi_app(environ, start_response)
  File "/home/pi/.local/lib/python3.5/site-packages/flask/app.py", line 2450, in wsgi_app
    response = self.handle_exception(e)
  File "/home/pi/.local/lib/python3.5/site-packages/flask/app.py", line 1867, in handle_exception
    reraise(exc_type, exc_value, tb)
  File "/home/pi/.local/lib/python3.5/site-packages/flask/_compat.py", line 39, in reraise
    raise value
  File "/home/pi/.local/lib/python3.5/site-packages/flask/app.py", line 2447, in wsgi_app
    response = self.full_dispatch_request()
  File "/home/pi/.local/lib/python3.5/site-packages/flask/app.py", line 1952, in full_dispatch_request
    rv = self.handle_user_exception(e)
  File "/home/pi/.local/lib/python3.5/site-packages/flask/app.py", line 1821, in handle_user_exception
    reraise(exc_type, exc_value, tb)
  File "/home/pi/.local/lib/python3.5/site-packages/flask/_compat.py", line 39, in reraise
    raise value
  File "/home/pi/.local/lib/python3.5/site-packages/flask/app.py", line 1950, in full_dispatch_request
    rv = self.dispatch_request()
  File "/home/pi/.local/lib/python3.5/site-packages/flask/app.py", line 1936, in dispatch_request
    return self.view_functions[rule.endpoint](**req.view_args)
  File "/home/pi/Desktop/brickpi2022/flask_app.py", line 105, in process_movement
    data = request.form.get()
TypeError: get() missing 1 required positional argument: 'key'
INFO:werkzeug:127.0.0.1 - - [23/Feb/2022 13:56:02] "[35m[1mPOST /process_movement HTTP/1.1[0m" 500 -
ERROR:werkzeug:Error on request:
Traceback (most recent call last):
  File "/home/pi/.local/lib/python3.5/site-packages/werkzeug/serving.py", line 323, in run_wsgi
    execute(self.server.app)
  File "/home/pi/.local/lib/python3.5/site-packages/werkzeug/serving.py", line 312, in execute
    application_iter = app(environ, start_response)
  File "/home/pi/.local/lib/python3.5/site-packages/flask/app.py", line 2464, in __call__
    return self.wsgi_app(environ, start_response)
  File "/home/pi/.local/lib/python3.5/site-packages/flask/app.py", line 2450, in wsgi_app
    response = self.handle_exception(e)
  File "/home/pi/.local/lib/python3.5/site-packages/flask/app.py", line 1867, in handle_exception
    reraise(exc_type, exc_value, tb)
  File "/home/pi/.local/lib/python3.5/site-packages/flask/_compat.py", line 39, in reraise
    raise value
  File "/home/pi/.local/lib/python3.5/site-packages/flask/app.py", line 2447, in wsgi_app
    response = self.full_dispatch_request()
  File "/home/pi/.local/lib/python3.5/site-packages/flask/app.py", line 1952, in full_dispatch_request
    rv = self.handle_user_exception(e)
  File "/home/pi/.local/lib/python3.5/site-packages/flask/app.py", line 1821, in handle_user_exception
    reraise(exc_type, exc_value, tb)
  File "/home/pi/.local/lib/python3.5/site-packages/flask/_compat.py", line 39, in reraise
    raise value
  File "/home/pi/.local/lib/python3.5/site-packages/flask/app.py", line 1950, in full_dispatch_request
    rv = self.dispatch_request()
  File "/home/pi/.local/lib/python3.5/site-packages/flask/app.py", line 1936, in dispatch_request
    return self.view_functions[rule.endpoint](**req.view_args)
  File "/home/pi/Desktop/brickpi2022/flask_app.py", line 105, in process_movement
    data = request.form.get()
TypeError: get() missing 1 required positional argument: 'key'
INFO:werkzeug:127.0.0.1 - - [23/Feb/2022 13:57:42] "[35m[1mPOST /process_movement HTTP/1.1[0m" 500 -
INFO:werkzeug:127.0.0.1 - - [23/Feb/2022 13:57:42] "[37mGET /dashboard HTTP/1.1[0m" 200 -
ERROR:werkzeug:Error on request:
Traceback (most recent call last):
  File "/home/pi/.local/lib/python3.5/site-packages/werkzeug/serving.py", line 323, in run_wsgi
    execute(self.server.app)
  File "/home/pi/.local/lib/python3.5/site-packages/werkzeug/serving.py", line 312, in execute
    application_iter = app(environ, start_response)
  File "/home/pi/.local/lib/python3.5/site-packages/flask/app.py", line 2464, in __call__
    return self.wsgi_app(environ, start_response)
  File "/home/pi/.local/lib/python3.5/site-packages/flask/app.py", line 2450, in wsgi_app
    response = self.handle_exception(e)
  File "/home/pi/.local/lib/python3.5/site-packages/flask/app.py", line 1867, in handle_exception
    reraise(exc_type, exc_value, tb)
  File "/home/pi/.local/lib/python3.5/site-packages/flask/_compat.py", line 39, in reraise
    raise value
  File "/home/pi/.local/lib/python3.5/site-packages/flask/app.py", line 2447, in wsgi_app
    response = self.full_dispatch_request()
  File "/home/pi/.local/lib/python3.5/site-packages/flask/app.py", line 1952, in full_dispatch_request
    rv = self.handle_user_exception(e)
  File "/home/pi/.local/lib/python3.5/site-packages/flask/app.py", line 1821, in handle_user_exception
    reraise(exc_type, exc_value, tb)
  File "/home/pi/.local/lib/python3.5/site-packages/flask/_compat.py", line 39, in reraise
    raise value
  File "/home/pi/.local/lib/python3.5/site-packages/flask/app.py", line 1950, in full_dispatch_request
    rv = self.dispatch_request()
  File "/home/pi/.local/lib/python3.5/site-packages/flask/app.py", line 1936, in dispatch_request
    return self.view_functions[rule.endpoint](**req.view_args)
  File "/home/pi/Desktop/brickpi2022/flask_app.py", line 105, in process_movement
    data = request.form.get()
TypeError: get() missing 1 required positional argument: 'key'
INFO:werkzeug:127.0.0.1 - - [23/Feb/2022 13:57:42] "[35m[1mPOST /process_movement HTTP/1.1[0m" 500 -
INFO:werkzeug:127.0.0.1 - - [23/Feb/2022 13:57:43] "[35m[1mPOST /process_movement HTTP/1.1[0m" 500 -
ERROR:werkzeug:Error on request:
Traceback (most recent call last):
  File "/home/pi/.local/lib/python3.5/site-packages/werkzeug/serving.py", line 323, in run_wsgi
    execute(self.server.app)
  File "/home/pi/.local/lib/python3.5/site-packages/werkzeug/serving.py", line 312, in execute
    application_iter = app(environ, start_response)
  File "/home/pi/.local/lib/python3.5/site-packages/flask/app.py", line 2464, in __call__
    return self.wsgi_app(environ, start_response)
  File "/home/pi/.local/lib/python3.5/site-packages/flask/app.py", line 2450, in wsgi_app
    response = self.handle_exception(e)
  File "/home/pi/.local/lib/python3.5/site-packages/flask/app.py", line 1867, in handle_exception
    reraise(exc_type, exc_value, tb)
  File "/home/pi/.local/lib/python3.5/site-packages/flask/_compat.py", line 39, in reraise
    raise value
  File "/home/pi/.local/lib/python3.5/site-packages/flask/app.py", line 2447, in wsgi_app
    response = self.full_dispatch_request()
  File "/home/pi/.local/lib/python3.5/site-packages/flask/app.py", line 1952, in full_dispatch_request
    rv = self.handle_user_exception(e)
  File "/home/pi/.local/lib/python3.5/site-packages/flask/app.py", line 1821, in handle_user_exception
    reraise(exc_type, exc_value, tb)
  File "/home/pi/.local/lib/python3.5/site-packages/flask/_compat.py", line 39, in reraise
    raise value
  File "/home/pi/.local/lib/python3.5/site-packages/flask/app.py", line 1950, in full_dispatch_request
    rv = self.dispatch_request()
  File "/home/pi/.local/lib/python3.5/site-packages/flask/app.py", line 1936, in dispatch_request
    return self.view_functions[rule.endpoint](**req.view_args)
  File "/home/pi/Desktop/brickpi2022/flask_app.py", line 105, in process_movement
    data = request.form.get()
TypeError: get() missing 1 required positional argument: 'key'
INFO:werkzeug:127.0.0.1 - - [23/Feb/2022 13:57:43] "[35m[1mPOST /process_movement HTTP/1.1[0m" 500 -
ERROR:werkzeug:Error on request:
Traceback (most recent call last):
  File "/home/pi/.local/lib/python3.5/site-packages/werkzeug/serving.py", line 323, in run_wsgi
    execute(self.server.app)
  File "/home/pi/.local/lib/python3.5/site-packages/werkzeug/serving.py", line 312, in execute
    application_iter = app(environ, start_response)
  File "/home/pi/.local/lib/python3.5/site-packages/flask/app.py", line 2464, in __call__
    return self.wsgi_app(environ, start_response)
  File "/home/pi/.local/lib/python3.5/site-packages/flask/app.py", line 2450, in wsgi_app
    response = self.handle_exception(e)
  File "/home/pi/.local/lib/python3.5/site-packages/flask/app.py", line 1867, in handle_exception
    reraise(exc_type, exc_value, tb)
  File "/home/pi/.local/lib/python3.5/site-packages/flask/_compat.py", line 39, in reraise
    raise value
  File "/home/pi/.local/lib/python3.5/site-packages/flask/app.py", line 2447, in wsgi_app
    response = self.full_dispatch_request()
  File "/home/pi/.local/lib/python3.5/site-packages/flask/app.py", line 1952, in full_dispatch_request
    rv = self.handle_user_exception(e)
  File "/home/pi/.local/lib/python3.5/site-packages/flask/app.py", line 1821, in handle_user_exception
    reraise(exc_type, exc_value, tb)
  File "/home/pi/.local/lib/python3.5/site-packages/flask/_compat.py", line 39, in reraise
    raise value
  File "/home/pi/.local/lib/python3.5/site-packages/flask/app.py", line 1950, in full_dispatch_request
    rv = self.dispatch_request()
  File "/home/pi/.local/lib/python3.5/site-packages/flask/app.py", line 1936, in dispatch_request
    return self.view_functions[rule.endpoint](**req.view_args)
  File "/home/pi/Desktop/brickpi2022/flask_app.py", line 105, in process_movement
    data = request.form.get()
TypeError: get() missing 1 required positional argument: 'key'
ERROR:werkzeug:Error on request:
Traceback (most recent call last):
  File "/home/pi/.local/lib/python3.5/site-packages/werkzeug/serving.py", line 323, in run_wsgi
    execute(self.server.app)
  File "/home/pi/.local/lib/python3.5/site-packages/werkzeug/serving.py", line 312, in execute
    application_iter = app(environ, start_response)
  File "/home/pi/.local/lib/python3.5/site-packages/flask/app.py", line 2464, in __call__
    return self.wsgi_app(environ, start_response)
  File "/home/pi/.local/lib/python3.5/site-packages/flask/app.py", line 2450, in wsgi_app
    response = self.handle_exception(e)
  File "/home/pi/.local/lib/python3.5/site-packages/flask/app.py", line 1867, in handle_exception
    reraise(exc_type, exc_value, tb)
  File "/home/pi/.local/lib/python3.5/site-packages/flask/_compat.py", line 39, in reraise
    raise value
  File "/home/pi/.local/lib/python3.5/site-packages/flask/app.py", line 2447, in wsgi_app
    response = self.full_dispatch_request()
  File "/home/pi/.local/lib/python3.5/site-packages/flask/app.py", line 1952, in full_dispatch_request
    rv = self.handle_user_exception(e)
  File "/home/pi/.local/lib/python3.5/site-packages/flask/app.py", line 1821, in handle_user_exception
    reraise(exc_type, exc_value, tb)
  File "/home/pi/.local/lib/python3.5/site-packages/flask/_compat.py", line 39, in reraise
    raise value
  File "/home/pi/.local/lib/python3.5/site-packages/flask/app.py", line 1950, in full_dispatch_request
    rv = self.dispatch_request()
  File "/home/pi/.local/lib/python3.5/site-packages/flask/app.py", line 1936, in dispatch_request
    return self.view_functions[rule.endpoint](**req.view_args)
  File "/home/pi/Desktop/brickpi2022/flask_app.py", line 105, in process_movement
    data = request.form.get()
TypeError: get() missing 1 required positional argument: 'key'
INFO:werkzeug:127.0.0.1 - - [23/Feb/2022 13:57:47] "[35m[1mPOST /process_movement HTTP/1.1[0m" 500 -
INFO:werkzeug:127.0.0.1 - - [23/Feb/2022 13:57:47] "[35m[1mPOST /process_movement HTTP/1.1[0m" 500 -
ERROR:werkzeug:Error on request:
Traceback (most recent call last):
  File "/home/pi/.local/lib/python3.5/site-packages/werkzeug/serving.py", line 323, in run_wsgi
    execute(self.server.app)
  File "/home/pi/.local/lib/python3.5/site-packages/werkzeug/serving.py", line 312, in execute
    application_iter = app(environ, start_response)
  File "/home/pi/.local/lib/python3.5/site-packages/flask/app.py", line 2464, in __call__
    return self.wsgi_app(environ, start_response)
  File "/home/pi/.local/lib/python3.5/site-packages/flask/app.py", line 2450, in wsgi_app
    response = self.handle_exception(e)
  File "/home/pi/.local/lib/python3.5/site-packages/flask/app.py", line 1867, in handle_exception
    reraise(exc_type, exc_value, tb)
  File "/home/pi/.local/lib/python3.5/site-packages/flask/_compat.py", line 39, in reraise
    raise value
  File "/home/pi/.local/lib/python3.5/site-packages/flask/app.py", line 2447, in wsgi_app
    response = self.full_dispatch_request()
  File "/home/pi/.local/lib/python3.5/site-packages/flask/app.py", line 1952, in full_dispatch_request
    rv = self.handle_user_exception(e)
  File "/home/pi/.local/lib/python3.5/site-packages/flask/app.py", line 1821, in handle_user_exception
    reraise(exc_type, exc_value, tb)
  File "/home/pi/.local/lib/python3.5/site-packages/flask/_compat.py", line 39, in reraise
    raise value
  File "/home/pi/.local/lib/python3.5/site-packages/flask/app.py", line 1950, in full_dispatch_request
    rv = self.dispatch_request()
  File "/home/pi/.local/lib/python3.5/site-packages/flask/app.py", line 1936, in dispatch_request
    return self.view_functions[rule.endpoint](**req.view_args)
  File "/home/pi/Desktop/brickpi2022/flask_app.py", line 105, in process_movement
    data = request.form.get()
TypeError: get() missing 1 required positional argument: 'key'
ERROR:werkzeug:Error on request:
Traceback (most recent call last):
  File "/home/pi/.local/lib/python3.5/site-packages/werkzeug/serving.py", line 323, in run_wsgi
    execute(self.server.app)
  File "/home/pi/.local/lib/python3.5/site-packages/werkzeug/serving.py", line 312, in execute
    application_iter = app(environ, start_response)
  File "/home/pi/.local/lib/python3.5/site-packages/flask/app.py", line 2464, in __call__
    return self.wsgi_app(environ, start_response)
  File "/home/pi/.local/lib/python3.5/site-packages/flask/app.py", line 2450, in wsgi_app
    response = self.handle_exception(e)
  File "/home/pi/.local/lib/python3.5/site-packages/flask/app.py", line 1867, in handle_exception
    reraise(exc_type, exc_value, tb)
  File "/home/pi/.local/lib/python3.5/site-packages/flask/_compat.py", line 39, in reraise
    raise value
  File "/home/pi/.local/lib/python3.5/site-packages/flask/app.py", line 2447, in wsgi_app
    response = self.full_dispatch_request()
  File "/home/pi/.local/lib/python3.5/site-packages/flask/app.py", line 1952, in full_dispatch_request
    rv = self.handle_user_exception(e)
  File "/home/pi/.local/lib/python3.5/site-packages/flask/app.py", line 1821, in handle_user_exception
    reraise(exc_type, exc_value, tb)
  File "/home/pi/.local/lib/python3.5/site-packages/flask/_compat.py", line 39, in reraise
    raise value
  File "/home/pi/.local/lib/python3.5/site-packages/flask/app.py", line 1950, in full_dispatch_request
    rv = self.dispatch_request()
  File "/home/pi/.local/lib/python3.5/site-packages/flask/app.py", line 1936, in dispatch_request
    return self.view_functions[rule.endpoint](**req.view_args)
  File "/home/pi/Desktop/brickpi2022/flask_app.py", line 105, in process_movement
    data = request.form.get()
TypeError: get() missing 1 required positional argument: 'key'
INFO:werkzeug:127.0.0.1 - - [23/Feb/2022 13:57:48] "[35m[1mPOST /process_movement HTTP/1.1[0m" 500 -
INFO:werkzeug:127.0.0.1 - - [23/Feb/2022 13:57:48] "[35m[1mPOST /process_movement HTTP/1.1[0m" 500 -
ERROR:werkzeug:Error on request:
Traceback (most recent call last):
  File "/home/pi/.local/lib/python3.5/site-packages/werkzeug/serving.py", line 323, in run_wsgi
    execute(self.server.app)
  File "/home/pi/.local/lib/python3.5/site-packages/werkzeug/serving.py", line 312, in execute
    application_iter = app(environ, start_response)
  File "/home/pi/.local/lib/python3.5/site-packages/flask/app.py", line 2464, in __call__
    return self.wsgi_app(environ, start_response)
  File "/home/pi/.local/lib/python3.5/site-packages/flask/app.py", line 2450, in wsgi_app
    response = self.handle_exception(e)
  File "/home/pi/.local/lib/python3.5/site-packages/flask/app.py", line 1867, in handle_exception
    reraise(exc_type, exc_value, tb)
  File "/home/pi/.local/lib/python3.5/site-packages/flask/_compat.py", line 39, in reraise
    raise value
  File "/home/pi/.local/lib/python3.5/site-packages/flask/app.py", line 2447, in wsgi_app
    response = self.full_dispatch_request()
  File "/home/pi/.local/lib/python3.5/site-packages/flask/app.py", line 1952, in full_dispatch_request
    rv = self.handle_user_exception(e)
  File "/home/pi/.local/lib/python3.5/site-packages/flask/app.py", line 1821, in handle_user_exception
    reraise(exc_type, exc_value, tb)
  File "/home/pi/.local/lib/python3.5/site-packages/flask/_compat.py", line 39, in reraise
    raise value
  File "/home/pi/.local/lib/python3.5/site-packages/flask/app.py", line 1950, in full_dispatch_request
    rv = self.dispatch_request()
  File "/home/pi/.local/lib/python3.5/site-packages/flask/app.py", line 1936, in dispatch_request
    return self.view_functions[rule.endpoint](**req.view_args)
  File "/home/pi/Desktop/brickpi2022/flask_app.py", line 105, in process_movement
    data = request.form.get()
TypeError: get() missing 1 required positional argument: 'key'
ERROR:werkzeug:Error on request:
Traceback (most recent call last):
  File "/home/pi/.local/lib/python3.5/site-packages/werkzeug/serving.py", line 323, in run_wsgi
    execute(self.server.app)
  File "/home/pi/.local/lib/python3.5/site-packages/werkzeug/serving.py", line 312, in execute
    application_iter = app(environ, start_response)
  File "/home/pi/.local/lib/python3.5/site-packages/flask/app.py", line 2464, in __call__
    return self.wsgi_app(environ, start_response)
  File "/home/pi/.local/lib/python3.5/site-packages/flask/app.py", line 2450, in wsgi_app
    response = self.handle_exception(e)
  File "/home/pi/.local/lib/python3.5/site-packages/flask/app.py", line 1867, in handle_exception
    reraise(exc_type, exc_value, tb)
  File "/home/pi/.local/lib/python3.5/site-packages/flask/_compat.py", line 39, in reraise
    raise value
  File "/home/pi/.local/lib/python3.5/site-packages/flask/app.py", line 2447, in wsgi_app
    response = self.full_dispatch_request()
  File "/home/pi/.local/lib/python3.5/site-packages/flask/app.py", line 1952, in full_dispatch_request
    rv = self.handle_user_exception(e)
  File "/home/pi/.local/lib/python3.5/site-packages/flask/app.py", line 1821, in handle_user_exception
    reraise(exc_type, exc_value, tb)
  File "/home/pi/.local/lib/python3.5/site-packages/flask/_compat.py", line 39, in reraise
    raise value
  File "/home/pi/.local/lib/python3.5/site-packages/flask/app.py", line 1950, in full_dispatch_request
    rv = self.dispatch_request()
  File "/home/pi/.local/lib/python3.5/site-packages/flask/app.py", line 1936, in dispatch_request
    return self.view_functions[rule.endpoint](**req.view_args)
  File "/home/pi/Desktop/brickpi2022/flask_app.py", line 105, in process_movement
    data = request.form.get()
TypeError: get() missing 1 required positional argument: 'key'
INFO:werkzeug:127.0.0.1 - - [23/Feb/2022 14:00:02] "[37mGET /dashboard HTTP/1.1[0m" 200 -
INFO:werkzeug:127.0.0.1 - - [23/Feb/2022 14:00:02] "[35m[1mPOST /process_movement HTTP/1.1[0m" 500 -
INFO:werkzeug:127.0.0.1 - - [23/Feb/2022 14:00:02] "[35m[1mPOST /process_movement HTTP/1.1[0m" 500 -
INFO:werkzeug:127.0.0.1 - - [23/Feb/2022 14:00:02] "[35m[1mPOST /process_movement HTTP/1.1[0m" 500 -
INFO:werkzeug:127.0.0.1 - - [23/Feb/2022 14:00:02] "[35m[1mPOST /process_movement HTTP/1.1[0m" 500 -
ERROR:werkzeug:Error on request:
Traceback (most recent call last):
  File "/home/pi/.local/lib/python3.5/site-packages/werkzeug/serving.py", line 323, in run_wsgi
    execute(self.server.app)
  File "/home/pi/.local/lib/python3.5/site-packages/werkzeug/serving.py", line 312, in execute
    application_iter = app(environ, start_response)
  File "/home/pi/.local/lib/python3.5/site-packages/flask/app.py", line 2464, in __call__
    return self.wsgi_app(environ, start_response)
  File "/home/pi/.local/lib/python3.5/site-packages/flask/app.py", line 2450, in wsgi_app
    response = self.handle_exception(e)
  File "/home/pi/.local/lib/python3.5/site-packages/flask/app.py", line 1867, in handle_exception
    reraise(exc_type, exc_value, tb)
  File "/home/pi/.local/lib/python3.5/site-packages/flask/_compat.py", line 39, in reraise
    raise value
  File "/home/pi/.local/lib/python3.5/site-packages/flask/app.py", line 2447, in wsgi_app
    response = self.full_dispatch_request()
  File "/home/pi/.local/lib/python3.5/site-packages/flask/app.py", line 1952, in full_dispatch_request
    rv = self.handle_user_exception(e)
  File "/home/pi/.local/lib/python3.5/site-packages/flask/app.py", line 1821, in handle_user_exception
    reraise(exc_type, exc_value, tb)
  File "/home/pi/.local/lib/python3.5/site-packages/flask/_compat.py", line 39, in reraise
    raise value
  File "/home/pi/.local/lib/python3.5/site-packages/flask/app.py", line 1950, in full_dispatch_request
    rv = self.dispatch_request()
  File "/home/pi/.local/lib/python3.5/site-packages/flask/app.py", line 1936, in dispatch_request
    return self.view_functions[rule.endpoint](**req.view_args)
  File "/home/pi/Desktop/brickpi2022/flask_app.py", line 105, in process_movement
    data = request.form.get()
TypeError: get() missing 1 required positional argument: 'key'
ERROR:werkzeug:Error on request:
Traceback (most recent call last):
  File "/home/pi/.local/lib/python3.5/site-packages/werkzeug/serving.py", line 323, in run_wsgi
    execute(self.server.app)
  File "/home/pi/.local/lib/python3.5/site-packages/werkzeug/serving.py", line 312, in execute
    application_iter = app(environ, start_response)
  File "/home/pi/.local/lib/python3.5/site-packages/flask/app.py", line 2464, in __call__
    return self.wsgi_app(environ, start_response)
  File "/home/pi/.local/lib/python3.5/site-packages/flask/app.py", line 2450, in wsgi_app
    response = self.handle_exception(e)
  File "/home/pi/.local/lib/python3.5/site-packages/flask/app.py", line 1867, in handle_exception
    reraise(exc_type, exc_value, tb)
  File "/home/pi/.local/lib/python3.5/site-packages/flask/_compat.py", line 39, in reraise
    raise value
  File "/home/pi/.local/lib/python3.5/site-packages/flask/app.py", line 2447, in wsgi_app
    response = self.full_dispatch_request()
  File "/home/pi/.local/lib/python3.5/site-packages/flask/app.py", line 1952, in full_dispatch_request
    rv = self.handle_user_exception(e)
  File "/home/pi/.local/lib/python3.5/site-packages/flask/app.py", line 1821, in handle_user_exception
    reraise(exc_type, exc_value, tb)
  File "/home/pi/.local/lib/python3.5/site-packages/flask/_compat.py", line 39, in reraise
    raise value
  File "/home/pi/.local/lib/python3.5/site-packages/flask/app.py", line 1950, in full_dispatch_request
    rv = self.dispatch_request()
  File "/home/pi/.local/lib/python3.5/site-packages/flask/app.py", line 1936, in dispatch_request
    return self.view_functions[rule.endpoint](**req.view_args)
  File "/home/pi/Desktop/brickpi2022/flask_app.py", line 105, in process_movement
    data = request.form.get()
TypeError: get() missing 1 required positional argument: 'key'
ERROR:werkzeug:Error on request:
Traceback (most recent call last):
  File "/home/pi/.local/lib/python3.5/site-packages/werkzeug/serving.py", line 323, in run_wsgi
    execute(self.server.app)
  File "/home/pi/.local/lib/python3.5/site-packages/werkzeug/serving.py", line 312, in execute
    application_iter = app(environ, start_response)
  File "/home/pi/.local/lib/python3.5/site-packages/flask/app.py", line 2464, in __call__
    return self.wsgi_app(environ, start_response)
  File "/home/pi/.local/lib/python3.5/site-packages/flask/app.py", line 2450, in wsgi_app
    response = self.handle_exception(e)
  File "/home/pi/.local/lib/python3.5/site-packages/flask/app.py", line 1867, in handle_exception
    reraise(exc_type, exc_value, tb)
  File "/home/pi/.local/lib/python3.5/site-packages/flask/_compat.py", line 39, in reraise
    raise value
  File "/home/pi/.local/lib/python3.5/site-packages/flask/app.py", line 2447, in wsgi_app
    response = self.full_dispatch_request()
  File "/home/pi/.local/lib/python3.5/site-packages/flask/app.py", line 1952, in full_dispatch_request
    rv = self.handle_user_exception(e)
  File "/home/pi/.local/lib/python3.5/site-packages/flask/app.py", line 1821, in handle_user_exception
    reraise(exc_type, exc_value, tb)
  File "/home/pi/.local/lib/python3.5/site-packages/flask/_compat.py", line 39, in reraise
    raise value
  File "/home/pi/.local/lib/python3.5/site-packages/flask/app.py", line 1950, in full_dispatch_request
    rv = self.dispatch_request()
  File "/home/pi/.local/lib/python3.5/site-packages/flask/app.py", line 1936, in dispatch_request
    return self.view_functions[rule.endpoint](**req.view_args)
  File "/home/pi/Desktop/brickpi2022/flask_app.py", line 105, in process_movement
    data = request.form.get()
TypeError: get() missing 1 required positional argument: 'key'
ERROR:werkzeug:Error on request:
Traceback (most recent call last):
  File "/home/pi/.local/lib/python3.5/site-packages/werkzeug/serving.py", line 323, in run_wsgi
    execute(self.server.app)
  File "/home/pi/.local/lib/python3.5/site-packages/werkzeug/serving.py", line 312, in execute
    application_iter = app(environ, start_response)
  File "/home/pi/.local/lib/python3.5/site-packages/flask/app.py", line 2464, in __call__
    return self.wsgi_app(environ, start_response)
  File "/home/pi/.local/lib/python3.5/site-packages/flask/app.py", line 2450, in wsgi_app
    response = self.handle_exception(e)
  File "/home/pi/.local/lib/python3.5/site-packages/flask/app.py", line 1867, in handle_exception
    reraise(exc_type, exc_value, tb)
  File "/home/pi/.local/lib/python3.5/site-packages/flask/_compat.py", line 39, in reraise
    raise value
  File "/home/pi/.local/lib/python3.5/site-packages/flask/app.py", line 2447, in wsgi_app
    response = self.full_dispatch_request()
  File "/home/pi/.local/lib/python3.5/site-packages/flask/app.py", line 1952, in full_dispatch_request
    rv = self.handle_user_exception(e)
  File "/home/pi/.local/lib/python3.5/site-packages/flask/app.py", line 1821, in handle_user_exception
    reraise(exc_type, exc_value, tb)
  File "/home/pi/.local/lib/python3.5/site-packages/flask/_compat.py", line 39, in reraise
    raise value
  File "/home/pi/.local/lib/python3.5/site-packages/flask/app.py", line 1950, in full_dispatch_request
    rv = self.dispatch_request()
  File "/home/pi/.local/lib/python3.5/site-packages/flask/app.py", line 1936, in dispatch_request
    return self.view_functions[rule.endpoint](**req.view_args)
  File "/home/pi/Desktop/brickpi2022/flask_app.py", line 105, in process_movement
    data = request.form.get()
TypeError: get() missing 1 required positional argument: 'key'
INFO:werkzeug: * Detected change in '/home/pi/Desktop/brickpi2022/flask_app.py', reloading
INFO:werkzeug: * Restarting with stat
INFO:werkzeug:127.0.0.1 - - [23/Feb/2022 14:00:38] "[35m[1mPOST /process_movement HTTP/1.1[0m" 500 -
INFO:werkzeug:127.0.0.1 - - [23/Feb/2022 14:00:38] "[35m[1mPOST /process_movement HTTP/1.1[0m" 500 -
ERROR:werkzeug:Error on request:
Traceback (most recent call last):
  File "/home/pi/.local/lib/python3.5/site-packages/werkzeug/serving.py", line 323, in run_wsgi
    execute(self.server.app)
  File "/home/pi/.local/lib/python3.5/site-packages/werkzeug/serving.py", line 312, in execute
    application_iter = app(environ, start_response)
  File "/home/pi/.local/lib/python3.5/site-packages/flask/app.py", line 2464, in __call__
    return self.wsgi_app(environ, start_response)
  File "/home/pi/.local/lib/python3.5/site-packages/flask/app.py", line 2450, in wsgi_app
    response = self.handle_exception(e)
  File "/home/pi/.local/lib/python3.5/site-packages/flask/app.py", line 1867, in handle_exception
    reraise(exc_type, exc_value, tb)
  File "/home/pi/.local/lib/python3.5/site-packages/flask/_compat.py", line 39, in reraise
    raise value
  File "/home/pi/.local/lib/python3.5/site-packages/flask/app.py", line 2447, in wsgi_app
    response = self.full_dispatch_request()
  File "/home/pi/.local/lib/python3.5/site-packages/flask/app.py", line 1952, in full_dispatch_request
    rv = self.handle_user_exception(e)
  File "/home/pi/.local/lib/python3.5/site-packages/flask/app.py", line 1821, in handle_user_exception
    reraise(exc_type, exc_value, tb)
  File "/home/pi/.local/lib/python3.5/site-packages/flask/_compat.py", line 39, in reraise
    raise value
  File "/home/pi/.local/lib/python3.5/site-packages/flask/app.py", line 1950, in full_dispatch_request
    rv = self.dispatch_request()
  File "/home/pi/.local/lib/python3.5/site-packages/flask/app.py", line 1936, in dispatch_request
    return self.view_functions[rule.endpoint](**req.view_args)
  File "/home/pi/Desktop/brickpi2022/flask_app.py", line 106, in process_movement
    data = request.form.get()
TypeError: get() missing 1 required positional argument: 'key'
ERROR:werkzeug:Error on request:
Traceback (most recent call last):
  File "/home/pi/.local/lib/python3.5/site-packages/werkzeug/serving.py", line 323, in run_wsgi
    execute(self.server.app)
  File "/home/pi/.local/lib/python3.5/site-packages/werkzeug/serving.py", line 312, in execute
    application_iter = app(environ, start_response)
  File "/home/pi/.local/lib/python3.5/site-packages/flask/app.py", line 2464, in __call__
    return self.wsgi_app(environ, start_response)
  File "/home/pi/.local/lib/python3.5/site-packages/flask/app.py", line 2450, in wsgi_app
    response = self.handle_exception(e)
  File "/home/pi/.local/lib/python3.5/site-packages/flask/app.py", line 1867, in handle_exception
    reraise(exc_type, exc_value, tb)
  File "/home/pi/.local/lib/python3.5/site-packages/flask/_compat.py", line 39, in reraise
    raise value
  File "/home/pi/.local/lib/python3.5/site-packages/flask/app.py", line 2447, in wsgi_app
    response = self.full_dispatch_request()
  File "/home/pi/.local/lib/python3.5/site-packages/flask/app.py", line 1952, in full_dispatch_request
    rv = self.handle_user_exception(e)
  File "/home/pi/.local/lib/python3.5/site-packages/flask/app.py", line 1821, in handle_user_exception
    reraise(exc_type, exc_value, tb)
  File "/home/pi/.local/lib/python3.5/site-packages/flask/_compat.py", line 39, in reraise
    raise value
  File "/home/pi/.local/lib/python3.5/site-packages/flask/app.py", line 1950, in full_dispatch_request
    rv = self.dispatch_request()
  File "/home/pi/.local/lib/python3.5/site-packages/flask/app.py", line 1936, in dispatch_request
    return self.view_functions[rule.endpoint](**req.view_args)
  File "/home/pi/Desktop/brickpi2022/flask_app.py", line 106, in process_movement
    data = request.form.get()
TypeError: get() missing 1 required positional argument: 'key'
INFO:werkzeug:127.0.0.1 - - [23/Feb/2022 14:00:38] "[37mGET /dashboard HTTP/1.1[0m" 200 -
INFO:werkzeug:127.0.0.1 - - [23/Feb/2022 14:00:39] "[35m[1mPOST /process_movement HTTP/1.1[0m" 500 -
INFO:werkzeug:127.0.0.1 - - [23/Feb/2022 14:00:39] "[35m[1mPOST /process_movement HTTP/1.1[0m" 500 -
ERROR:werkzeug:Error on request:
Traceback (most recent call last):
  File "/home/pi/.local/lib/python3.5/site-packages/werkzeug/serving.py", line 323, in run_wsgi
    execute(self.server.app)
  File "/home/pi/.local/lib/python3.5/site-packages/werkzeug/serving.py", line 312, in execute
    application_iter = app(environ, start_response)
  File "/home/pi/.local/lib/python3.5/site-packages/flask/app.py", line 2464, in __call__
    return self.wsgi_app(environ, start_response)
  File "/home/pi/.local/lib/python3.5/site-packages/flask/app.py", line 2450, in wsgi_app
    response = self.handle_exception(e)
  File "/home/pi/.local/lib/python3.5/site-packages/flask/app.py", line 1867, in handle_exception
    reraise(exc_type, exc_value, tb)
  File "/home/pi/.local/lib/python3.5/site-packages/flask/_compat.py", line 39, in reraise
    raise value
  File "/home/pi/.local/lib/python3.5/site-packages/flask/app.py", line 2447, in wsgi_app
    response = self.full_dispatch_request()
  File "/home/pi/.local/lib/python3.5/site-packages/flask/app.py", line 1952, in full_dispatch_request
    rv = self.handle_user_exception(e)
  File "/home/pi/.local/lib/python3.5/site-packages/flask/app.py", line 1821, in handle_user_exception
    reraise(exc_type, exc_value, tb)
  File "/home/pi/.local/lib/python3.5/site-packages/flask/_compat.py", line 39, in reraise
    raise value
  File "/home/pi/.local/lib/python3.5/site-packages/flask/app.py", line 1950, in full_dispatch_request
    rv = self.dispatch_request()
  File "/home/pi/.local/lib/python3.5/site-packages/flask/app.py", line 1936, in dispatch_request
    return self.view_functions[rule.endpoint](**req.view_args)
  File "/home/pi/Desktop/brickpi2022/flask_app.py", line 106, in process_movement
    data = request.form.get()
TypeError: get() missing 1 required positional argument: 'key'
ERROR:werkzeug:Error on request:
Traceback (most recent call last):
  File "/home/pi/.local/lib/python3.5/site-packages/werkzeug/serving.py", line 323, in run_wsgi
    execute(self.server.app)
  File "/home/pi/.local/lib/python3.5/site-packages/werkzeug/serving.py", line 312, in execute
    application_iter = app(environ, start_response)
  File "/home/pi/.local/lib/python3.5/site-packages/flask/app.py", line 2464, in __call__
    return self.wsgi_app(environ, start_response)
  File "/home/pi/.local/lib/python3.5/site-packages/flask/app.py", line 2450, in wsgi_app
    response = self.handle_exception(e)
  File "/home/pi/.local/lib/python3.5/site-packages/flask/app.py", line 1867, in handle_exception
    reraise(exc_type, exc_value, tb)
  File "/home/pi/.local/lib/python3.5/site-packages/flask/_compat.py", line 39, in reraise
    raise value
  File "/home/pi/.local/lib/python3.5/site-packages/flask/app.py", line 2447, in wsgi_app
    response = self.full_dispatch_request()
  File "/home/pi/.local/lib/python3.5/site-packages/flask/app.py", line 1952, in full_dispatch_request
    rv = self.handle_user_exception(e)
  File "/home/pi/.local/lib/python3.5/site-packages/flask/app.py", line 1821, in handle_user_exception
    reraise(exc_type, exc_value, tb)
  File "/home/pi/.local/lib/python3.5/site-packages/flask/_compat.py", line 39, in reraise
    raise value
  File "/home/pi/.local/lib/python3.5/site-packages/flask/app.py", line 1950, in full_dispatch_request
    rv = self.dispatch_request()
  File "/home/pi/.local/lib/python3.5/site-packages/flask/app.py", line 1936, in dispatch_request
    return self.view_functions[rule.endpoint](**req.view_args)
  File "/home/pi/Desktop/brickpi2022/flask_app.py", line 106, in process_movement
    data = request.form.get()
TypeError: get() missing 1 required positional argument: 'key'
INFO:werkzeug:127.0.0.1 - - [23/Feb/2022 14:00:41] "[35m[1mPOST /process_movement HTTP/1.1[0m" 500 -
ERROR:werkzeug:Error on request:
Traceback (most recent call last):
  File "/home/pi/.local/lib/python3.5/site-packages/werkzeug/serving.py", line 323, in run_wsgi
    execute(self.server.app)
  File "/home/pi/.local/lib/python3.5/site-packages/werkzeug/serving.py", line 312, in execute
    application_iter = app(environ, start_response)
  File "/home/pi/.local/lib/python3.5/site-packages/flask/app.py", line 2464, in __call__
    return self.wsgi_app(environ, start_response)
  File "/home/pi/.local/lib/python3.5/site-packages/flask/app.py", line 2450, in wsgi_app
    response = self.handle_exception(e)
  File "/home/pi/.local/lib/python3.5/site-packages/flask/app.py", line 1867, in handle_exception
    reraise(exc_type, exc_value, tb)
  File "/home/pi/.local/lib/python3.5/site-packages/flask/_compat.py", line 39, in reraise
    raise value
  File "/home/pi/.local/lib/python3.5/site-packages/flask/app.py", line 2447, in wsgi_app
    response = self.full_dispatch_request()
  File "/home/pi/.local/lib/python3.5/site-packages/flask/app.py", line 1952, in full_dispatch_request
    rv = self.handle_user_exception(e)
  File "/home/pi/.local/lib/python3.5/site-packages/flask/app.py", line 1821, in handle_user_exception
    reraise(exc_type, exc_value, tb)
  File "/home/pi/.local/lib/python3.5/site-packages/flask/_compat.py", line 39, in reraise
    raise value
  File "/home/pi/.local/lib/python3.5/site-packages/flask/app.py", line 1950, in full_dispatch_request
    rv = self.dispatch_request()
  File "/home/pi/.local/lib/python3.5/site-packages/flask/app.py", line 1936, in dispatch_request
    return self.view_functions[rule.endpoint](**req.view_args)
  File "/home/pi/Desktop/brickpi2022/flask_app.py", line 106, in process_movement
    data = request.form.get()
TypeError: get() missing 1 required positional argument: 'key'
INFO:werkzeug:127.0.0.1 - - [23/Feb/2022 14:00:41] "[35m[1mPOST /process_movement HTTP/1.1[0m" 500 -
ERROR:werkzeug:Error on request:
Traceback (most recent call last):
  File "/home/pi/.local/lib/python3.5/site-packages/werkzeug/serving.py", line 323, in run_wsgi
    execute(self.server.app)
  File "/home/pi/.local/lib/python3.5/site-packages/werkzeug/serving.py", line 312, in execute
    application_iter = app(environ, start_response)
  File "/home/pi/.local/lib/python3.5/site-packages/flask/app.py", line 2464, in __call__
    return self.wsgi_app(environ, start_response)
  File "/home/pi/.local/lib/python3.5/site-packages/flask/app.py", line 2450, in wsgi_app
    response = self.handle_exception(e)
  File "/home/pi/.local/lib/python3.5/site-packages/flask/app.py", line 1867, in handle_exception
    reraise(exc_type, exc_value, tb)
  File "/home/pi/.local/lib/python3.5/site-packages/flask/_compat.py", line 39, in reraise
    raise value
  File "/home/pi/.local/lib/python3.5/site-packages/flask/app.py", line 2447, in wsgi_app
    response = self.full_dispatch_request()
  File "/home/pi/.local/lib/python3.5/site-packages/flask/app.py", line 1952, in full_dispatch_request
    rv = self.handle_user_exception(e)
  File "/home/pi/.local/lib/python3.5/site-packages/flask/app.py", line 1821, in handle_user_exception
    reraise(exc_type, exc_value, tb)
  File "/home/pi/.local/lib/python3.5/site-packages/flask/_compat.py", line 39, in reraise
    raise value
  File "/home/pi/.local/lib/python3.5/site-packages/flask/app.py", line 1950, in full_dispatch_request
    rv = self.dispatch_request()
  File "/home/pi/.local/lib/python3.5/site-packages/flask/app.py", line 1936, in dispatch_request
    return self.view_functions[rule.endpoint](**req.view_args)
  File "/home/pi/Desktop/brickpi2022/flask_app.py", line 106, in process_movement
    data = request.form.get()
TypeError: get() missing 1 required positional argument: 'key'
INFO:werkzeug: * Detected change in '/home/pi/Desktop/brickpi2022/flask_app.py', reloading
INFO:werkzeug: * Restarting with stat
INFO:werkzeug:127.0.0.1 - - [23/Feb/2022 14:03:28] "[37mGET /dashboard HTTP/1.1[0m" 200 -
INFO:werkzeug:127.0.0.1 - - [23/Feb/2022 14:03:28] "[35m[1mPOST /process_movement HTTP/1.1[0m" 500 -
INFO:werkzeug:127.0.0.1 - - [23/Feb/2022 14:03:28] "[35m[1mPOST /process_movement HTTP/1.1[0m" 500 -
INFO:werkzeug:127.0.0.1 - - [23/Feb/2022 14:03:28] "[35m[1mPOST /process_movement HTTP/1.1[0m" 500 -
INFO:werkzeug:127.0.0.1 - - [23/Feb/2022 14:03:28] "[35m[1mPOST /process_movement HTTP/1.1[0m" 500 -
ERROR:werkzeug:Error on request:
Traceback (most recent call last):
  File "/home/pi/.local/lib/python3.5/site-packages/werkzeug/serving.py", line 323, in run_wsgi
    execute(self.server.app)
  File "/home/pi/.local/lib/python3.5/site-packages/werkzeug/serving.py", line 312, in execute
    application_iter = app(environ, start_response)
  File "/home/pi/.local/lib/python3.5/site-packages/flask/app.py", line 2464, in __call__
    return self.wsgi_app(environ, start_response)
  File "/home/pi/.local/lib/python3.5/site-packages/flask/app.py", line 2450, in wsgi_app
    response = self.handle_exception(e)
  File "/home/pi/.local/lib/python3.5/site-packages/flask/app.py", line 1867, in handle_exception
    reraise(exc_type, exc_value, tb)
  File "/home/pi/.local/lib/python3.5/site-packages/flask/_compat.py", line 39, in reraise
    raise value
  File "/home/pi/.local/lib/python3.5/site-packages/flask/app.py", line 2447, in wsgi_app
    response = self.full_dispatch_request()
  File "/home/pi/.local/lib/python3.5/site-packages/flask/app.py", line 1953, in full_dispatch_request
    return self.finalize_request(rv)
  File "/home/pi/.local/lib/python3.5/site-packages/flask/app.py", line 1968, in finalize_request
    response = self.make_response(rv)
  File "/home/pi/.local/lib/python3.5/site-packages/flask/app.py", line 2098, in make_response
    "The view function did not return a valid response. The"
TypeError: The view function did not return a valid response. The function either returned None or ended without a return statement.
ERROR:werkzeug:Error on request:
Traceback (most recent call last):
  File "/home/pi/.local/lib/python3.5/site-packages/werkzeug/serving.py", line 323, in run_wsgi
    execute(self.server.app)
  File "/home/pi/.local/lib/python3.5/site-packages/werkzeug/serving.py", line 312, in execute
    application_iter = app(environ, start_response)
  File "/home/pi/.local/lib/python3.5/site-packages/flask/app.py", line 2464, in __call__
    return self.wsgi_app(environ, start_response)
  File "/home/pi/.local/lib/python3.5/site-packages/flask/app.py", line 2450, in wsgi_app
    response = self.handle_exception(e)
  File "/home/pi/.local/lib/python3.5/site-packages/flask/app.py", line 1867, in handle_exception
    reraise(exc_type, exc_value, tb)
  File "/home/pi/.local/lib/python3.5/site-packages/flask/_compat.py", line 39, in reraise
    raise value
  File "/home/pi/.local/lib/python3.5/site-packages/flask/app.py", line 2447, in wsgi_app
    response = self.full_dispatch_request()
  File "/home/pi/.local/lib/python3.5/site-packages/flask/app.py", line 1953, in full_dispatch_request
    return self.finalize_request(rv)
  File "/home/pi/.local/lib/python3.5/site-packages/flask/app.py", line 1968, in finalize_request
    response = self.make_response(rv)
  File "/home/pi/.local/lib/python3.5/site-packages/flask/app.py", line 2098, in make_response
    "The view function did not return a valid response. The"
TypeError: The view function did not return a valid response. The function either returned None or ended without a return statement.
ERROR:werkzeug:Error on request:
Traceback (most recent call last):
  File "/home/pi/.local/lib/python3.5/site-packages/werkzeug/serving.py", line 323, in run_wsgi
    execute(self.server.app)
  File "/home/pi/.local/lib/python3.5/site-packages/werkzeug/serving.py", line 312, in execute
    application_iter = app(environ, start_response)
  File "/home/pi/.local/lib/python3.5/site-packages/flask/app.py", line 2464, in __call__
    return self.wsgi_app(environ, start_response)
  File "/home/pi/.local/lib/python3.5/site-packages/flask/app.py", line 2450, in wsgi_app
    response = self.handle_exception(e)
  File "/home/pi/.local/lib/python3.5/site-packages/flask/app.py", line 1867, in handle_exception
    reraise(exc_type, exc_value, tb)
  File "/home/pi/.local/lib/python3.5/site-packages/flask/_compat.py", line 39, in reraise
    raise value
  File "/home/pi/.local/lib/python3.5/site-packages/flask/app.py", line 2447, in wsgi_app
    response = self.full_dispatch_request()
  File "/home/pi/.local/lib/python3.5/site-packages/flask/app.py", line 1953, in full_dispatch_request
    return self.finalize_request(rv)
  File "/home/pi/.local/lib/python3.5/site-packages/flask/app.py", line 1968, in finalize_request
    response = self.make_response(rv)
  File "/home/pi/.local/lib/python3.5/site-packages/flask/app.py", line 2098, in make_response
    "The view function did not return a valid response. The"
TypeError: The view function did not return a valid response. The function either returned None or ended without a return statement.
ERROR:werkzeug:Error on request:
Traceback (most recent call last):
  File "/home/pi/.local/lib/python3.5/site-packages/werkzeug/serving.py", line 323, in run_wsgi
    execute(self.server.app)
  File "/home/pi/.local/lib/python3.5/site-packages/werkzeug/serving.py", line 312, in execute
    application_iter = app(environ, start_response)
  File "/home/pi/.local/lib/python3.5/site-packages/flask/app.py", line 2464, in __call__
    return self.wsgi_app(environ, start_response)
  File "/home/pi/.local/lib/python3.5/site-packages/flask/app.py", line 2450, in wsgi_app
    response = self.handle_exception(e)
  File "/home/pi/.local/lib/python3.5/site-packages/flask/app.py", line 1867, in handle_exception
    reraise(exc_type, exc_value, tb)
  File "/home/pi/.local/lib/python3.5/site-packages/flask/_compat.py", line 39, in reraise
    raise value
  File "/home/pi/.local/lib/python3.5/site-packages/flask/app.py", line 2447, in wsgi_app
    response = self.full_dispatch_request()
  File "/home/pi/.local/lib/python3.5/site-packages/flask/app.py", line 1953, in full_dispatch_request
    return self.finalize_request(rv)
  File "/home/pi/.local/lib/python3.5/site-packages/flask/app.py", line 1968, in finalize_request
    response = self.make_response(rv)
  File "/home/pi/.local/lib/python3.5/site-packages/flask/app.py", line 2098, in make_response
    "The view function did not return a valid response. The"
TypeError: The view function did not return a valid response. The function either returned None or ended without a return statement.
INFO:werkzeug:127.0.0.1 - - [23/Feb/2022 14:03:29] "[35m[1mPOST /process_movement HTTP/1.1[0m" 500 -
ERROR:werkzeug:Error on request:
Traceback (most recent call last):
  File "/home/pi/.local/lib/python3.5/site-packages/werkzeug/serving.py", line 323, in run_wsgi
    execute(self.server.app)
  File "/home/pi/.local/lib/python3.5/site-packages/werkzeug/serving.py", line 312, in execute
    application_iter = app(environ, start_response)
  File "/home/pi/.local/lib/python3.5/site-packages/flask/app.py", line 2464, in __call__
    return self.wsgi_app(environ, start_response)
  File "/home/pi/.local/lib/python3.5/site-packages/flask/app.py", line 2450, in wsgi_app
    response = self.handle_exception(e)
  File "/home/pi/.local/lib/python3.5/site-packages/flask/app.py", line 1867, in handle_exception
    reraise(exc_type, exc_value, tb)
  File "/home/pi/.local/lib/python3.5/site-packages/flask/_compat.py", line 39, in reraise
    raise value
  File "/home/pi/.local/lib/python3.5/site-packages/flask/app.py", line 2447, in wsgi_app
    response = self.full_dispatch_request()
  File "/home/pi/.local/lib/python3.5/site-packages/flask/app.py", line 1953, in full_dispatch_request
    return self.finalize_request(rv)
  File "/home/pi/.local/lib/python3.5/site-packages/flask/app.py", line 1968, in finalize_request
    response = self.make_response(rv)
  File "/home/pi/.local/lib/python3.5/site-packages/flask/app.py", line 2098, in make_response
    "The view function did not return a valid response. The"
TypeError: The view function did not return a valid response. The function either returned None or ended without a return statement.
INFO:werkzeug:127.0.0.1 - - [23/Feb/2022 14:03:29] "[35m[1mPOST /process_movement HTTP/1.1[0m" 500 -
ERROR:werkzeug:Error on request:
Traceback (most recent call last):
  File "/home/pi/.local/lib/python3.5/site-packages/werkzeug/serving.py", line 323, in run_wsgi
    execute(self.server.app)
  File "/home/pi/.local/lib/python3.5/site-packages/werkzeug/serving.py", line 312, in execute
    application_iter = app(environ, start_response)
  File "/home/pi/.local/lib/python3.5/site-packages/flask/app.py", line 2464, in __call__
    return self.wsgi_app(environ, start_response)
  File "/home/pi/.local/lib/python3.5/site-packages/flask/app.py", line 2450, in wsgi_app
    response = self.handle_exception(e)
  File "/home/pi/.local/lib/python3.5/site-packages/flask/app.py", line 1867, in handle_exception
    reraise(exc_type, exc_value, tb)
  File "/home/pi/.local/lib/python3.5/site-packages/flask/_compat.py", line 39, in reraise
    raise value
  File "/home/pi/.local/lib/python3.5/site-packages/flask/app.py", line 2447, in wsgi_app
    response = self.full_dispatch_request()
  File "/home/pi/.local/lib/python3.5/site-packages/flask/app.py", line 1953, in full_dispatch_request
    return self.finalize_request(rv)
  File "/home/pi/.local/lib/python3.5/site-packages/flask/app.py", line 1968, in finalize_request
    response = self.make_response(rv)
  File "/home/pi/.local/lib/python3.5/site-packages/flask/app.py", line 2098, in make_response
    "The view function did not return a valid response. The"
TypeError: The view function did not return a valid response. The function either returned None or ended without a return statement.
INFO:werkzeug:127.0.0.1 - - [23/Feb/2022 14:03:31] "[35m[1mPOST /process_movement HTTP/1.1[0m" 500 -
ERROR:werkzeug:Error on request:
Traceback (most recent call last):
  File "/home/pi/.local/lib/python3.5/site-packages/werkzeug/serving.py", line 323, in run_wsgi
    execute(self.server.app)
  File "/home/pi/.local/lib/python3.5/site-packages/werkzeug/serving.py", line 312, in execute
    application_iter = app(environ, start_response)
  File "/home/pi/.local/lib/python3.5/site-packages/flask/app.py", line 2464, in __call__
    return self.wsgi_app(environ, start_response)
  File "/home/pi/.local/lib/python3.5/site-packages/flask/app.py", line 2450, in wsgi_app
    response = self.handle_exception(e)
  File "/home/pi/.local/lib/python3.5/site-packages/flask/app.py", line 1867, in handle_exception
    reraise(exc_type, exc_value, tb)
  File "/home/pi/.local/lib/python3.5/site-packages/flask/_compat.py", line 39, in reraise
    raise value
  File "/home/pi/.local/lib/python3.5/site-packages/flask/app.py", line 2447, in wsgi_app
    response = self.full_dispatch_request()
  File "/home/pi/.local/lib/python3.5/site-packages/flask/app.py", line 1953, in full_dispatch_request
    return self.finalize_request(rv)
  File "/home/pi/.local/lib/python3.5/site-packages/flask/app.py", line 1968, in finalize_request
    response = self.make_response(rv)
  File "/home/pi/.local/lib/python3.5/site-packages/flask/app.py", line 2098, in make_response
    "The view function did not return a valid response. The"
TypeError: The view function did not return a valid response. The function either returned None or ended without a return statement.
INFO:werkzeug:127.0.0.1 - - [23/Feb/2022 14:03:32] "[35m[1mPOST /process_movement HTTP/1.1[0m" 500 -
ERROR:werkzeug:Error on request:
Traceback (most recent call last):
  File "/home/pi/.local/lib/python3.5/site-packages/werkzeug/serving.py", line 323, in run_wsgi
    execute(self.server.app)
  File "/home/pi/.local/lib/python3.5/site-packages/werkzeug/serving.py", line 312, in execute
    application_iter = app(environ, start_response)
  File "/home/pi/.local/lib/python3.5/site-packages/flask/app.py", line 2464, in __call__
    return self.wsgi_app(environ, start_response)
  File "/home/pi/.local/lib/python3.5/site-packages/flask/app.py", line 2450, in wsgi_app
    response = self.handle_exception(e)
  File "/home/pi/.local/lib/python3.5/site-packages/flask/app.py", line 1867, in handle_exception
    reraise(exc_type, exc_value, tb)
  File "/home/pi/.local/lib/python3.5/site-packages/flask/_compat.py", line 39, in reraise
    raise value
  File "/home/pi/.local/lib/python3.5/site-packages/flask/app.py", line 2447, in wsgi_app
    response = self.full_dispatch_request()
  File "/home/pi/.local/lib/python3.5/site-packages/flask/app.py", line 1953, in full_dispatch_request
    return self.finalize_request(rv)
  File "/home/pi/.local/lib/python3.5/site-packages/flask/app.py", line 1968, in finalize_request
    response = self.make_response(rv)
  File "/home/pi/.local/lib/python3.5/site-packages/flask/app.py", line 2098, in make_response
    "The view function did not return a valid response. The"
TypeError: The view function did not return a valid response. The function either returned None or ended without a return statement.
INFO:werkzeug: * Detected change in '/home/pi/Desktop/brickpi2022/flask_app.py', reloading
INFO:werkzeug: * Restarting with stat
INFO:werkzeug:127.0.0.1 - - [23/Feb/2022 14:04:37] "[37mPOST /process_movement HTTP/1.1[0m" 200 -
INFO:werkzeug:127.0.0.1 - - [23/Feb/2022 14:04:37] "[37mPOST /process_movement HTTP/1.1[0m" 200 -
INFO:werkzeug:127.0.0.1 - - [23/Feb/2022 14:04:37] "[37mPOST /process_movement HTTP/1.1[0m" 200 -
INFO:werkzeug:127.0.0.1 - - [23/Feb/2022 14:04:37] "[37mPOST /process_movement HTTP/1.1[0m" 200 -
INFO:werkzeug:127.0.0.1 - - [23/Feb/2022 14:04:37] "[37mGET /dashboard HTTP/1.1[0m" 200 -
INFO:werkzeug:127.0.0.1 - - [23/Feb/2022 14:04:40] "[37mPOST /process_movement HTTP/1.1[0m" 200 -
INFO:werkzeug:127.0.0.1 - - [23/Feb/2022 14:04:40] "[37mPOST /process_movement HTTP/1.1[0m" 200 -
INFO:werkzeug: * Detected change in '/home/pi/Desktop/brickpi2022/flask_app.py', reloading
INFO:werkzeug: * Restarting with stat
INFO:werkzeug:127.0.0.1 - - [23/Feb/2022 14:05:03] "[37mPOST /process_movement HTTP/1.1[0m" 200 -
INFO:werkzeug:127.0.0.1 - - [23/Feb/2022 14:05:04] "[37mGET /dashboard HTTP/1.1[0m" 200 -
INFO:werkzeug:127.0.0.1 - - [23/Feb/2022 14:05:04] "[37mPOST /process_movement HTTP/1.1[0m" 200 -
INFO:werkzeug:127.0.0.1 - - [23/Feb/2022 14:05:04] "[37mPOST /process_movement HTTP/1.1[0m" 200 -
INFO:werkzeug:127.0.0.1 - - [23/Feb/2022 14:05:04] "[37mPOST /process_movement HTTP/1.1[0m" 200 -
INFO:werkzeug:127.0.0.1 - - [23/Feb/2022 14:05:06] "[37mPOST /process_movement HTTP/1.1[0m" 200 -
INFO:werkzeug:127.0.0.1 - - [23/Feb/2022 14:05:06] "[37mPOST /process_movement HTTP/1.1[0m" 200 -
INFO:werkzeug: * Detected change in '/home/pi/Desktop/brickpi2022/flask_app.py', reloading
INFO:werkzeug: * Restarting with stat
INFO:werkzeug:127.0.0.1 - - [23/Feb/2022 14:06:07] "[37mPOST /process_movement HTTP/1.1[0m" 200 -
INFO:werkzeug:127.0.0.1 - - [23/Feb/2022 14:06:08] "[37mGET /dashboard HTTP/1.1[0m" 200 -
INFO:werkzeug:127.0.0.1 - - [23/Feb/2022 14:06:08] "[37mPOST /process_movement HTTP/1.1[0m" 200 -
INFO:werkzeug:127.0.0.1 - - [23/Feb/2022 14:06:13] "[37mPOST /process_movement HTTP/1.1[0m" 200 -
INFO:werkzeug:127.0.0.1 - - [23/Feb/2022 14:06:13] "[37mPOST /process_movement HTTP/1.1[0m" 200 -
INFO:werkzeug: * Detected change in '/home/pi/Desktop/brickpi2022/flask_app.py', reloading
INFO:werkzeug: * Restarting with stat
INFO:werkzeug:127.0.0.1 - - [23/Feb/2022 14:07:15] "[37mPOST /process_movement HTTP/1.1[0m" 200 -
INFO:werkzeug:127.0.0.1 - - [23/Feb/2022 14:07:15] "[37mPOST /process_movement HTTP/1.1[0m" 200 -
INFO:werkzeug:127.0.0.1 - - [23/Feb/2022 14:07:15] "[37mGET /dashboard HTTP/1.1[0m" 200 -
INFO:werkzeug:127.0.0.1 - - [23/Feb/2022 14:07:15] "[37mPOST /process_movement HTTP/1.1[0m" 200 -
INFO:werkzeug:127.0.0.1 - - [23/Feb/2022 14:07:15] "[37mPOST /process_movement HTTP/1.1[0m" 200 -
INFO:werkzeug:127.0.0.1 - - [25/Feb/2022 23:21:41] "[35m[1mGET / HTTP/1.1[0m" 500 -
ERROR:werkzeug:Error on request:
Traceback (most recent call last):
  File "/home/pi/.local/lib/python3.5/site-packages/werkzeug/serving.py", line 323, in run_wsgi
    execute(self.server.app)
  File "/home/pi/.local/lib/python3.5/site-packages/werkzeug/serving.py", line 312, in execute
    application_iter = app(environ, start_response)
  File "/home/pi/Desktop/brickpi2022/flask_app.py", line 13, in <module>
    DATABASE = Database('databases/U3_SIA2_Rescue_Database-V1.db')
NameError: name 'Database' is not defined
INFO:werkzeug:127.0.0.1 - - [25/Feb/2022 23:21:59] "[35m[1mGET / HTTP/1.1[0m" 500 -
ERROR:werkzeug:Error on request:
Traceback (most recent call last):
  File "/home/pi/.local/lib/python3.5/site-packages/werkzeug/serving.py", line 323, in run_wsgi
    execute(self.server.app)
  File "/home/pi/.local/lib/python3.5/site-packages/werkzeug/serving.py", line 312, in execute
    application_iter = app(environ, start_response)
  File "/home/pi/Desktop/brickpi2022/flask_app.py", line 13, in <module>
    DATABASE = databaseinterface.Database('databases/U3_SIA2_Rescue_Database-V1.db')
AttributeError: module 'interfaces.databaseinterface' has no attribute 'Database'
INFO:werkzeug:127.0.0.1 - - [25/Feb/2022 23:22:01] "[35m[1mGET / HTTP/1.1[0m" 500 -
ERROR:werkzeug:Error on request:
Traceback (most recent call last):
  File "/home/pi/.local/lib/python3.5/site-packages/werkzeug/serving.py", line 323, in run_wsgi
    execute(self.server.app)
  File "/home/pi/.local/lib/python3.5/site-packages/werkzeug/serving.py", line 312, in execute
    application_iter = app(environ, start_response)
  File "/home/pi/Desktop/brickpi2022/flask_app.py", line 13, in <module>
    DATABASE = databaseinterface.Database('databases/U3_SIA2_Rescue_Database-V1.db')
AttributeError: module 'interfaces.databaseinterface' has no attribute 'Database'
INFO:werkzeug:127.0.0.1 - - [25/Feb/2022 23:22:14] "[32mGET / HTTP/1.1[0m" 302 -
INFO:werkzeug:127.0.0.1 - - [25/Feb/2022 23:22:14] "[37mGET /dashboard HTTP/1.1[0m" 200 -
INFO:werkzeug:127.0.0.1 - - [25/Feb/2022 23:22:14] "[36mGET /static/css/theme.css HTTP/1.1[0m" 304 -
INFO:werkzeug:127.0.0.1 - - [25/Feb/2022 23:22:14] "[37mGET /static/js/custom.js HTTP/1.1[0m" 200 -
INFO:werkzeug:127.0.0.1 - - [25/Feb/2022 23:22:14] "[37mGET /static/js/new_ajax_helper.js HTTP/1.1[0m" 200 -
INFO:werkzeug:127.0.0.1 - - [25/Feb/2022 23:22:14] "[36mGET /static/css/custom.css HTTP/1.1[0m" 304 -
INFO:werkzeug:127.0.0.1 - - [25/Feb/2022 23:22:14] "[37mGET /static/js/dashboard.js HTTP/1.1[0m" 200 -
INFO:werkzeug:127.0.0.1 - - [25/Feb/2022 23:22:14] "[37mGET /static/js/mapping.js HTTP/1.1[0m" 200 -
INFO:werkzeug:127.0.0.1 - - [25/Feb/2022 23:22:14] "[37mGET /static/js/brick_pi_2022_dashboard.js HTTP/1.1[0m" 200 -
INFO:werkzeug: * Detected change in '/home/pi/Desktop/brickpi2022/flask_app.py', reloading
INFO:werkzeug:127.0.0.1 - - [25/Feb/2022 23:23:04] "[37mGET /dashboard HTTP/1.1[0m" 200 -
INFO:flask_app:LOADING CAMERA
INFO:root:CAMERA INTERFACE: Started Camera Thread
INFO:flask_app:LOADING THE ROBOT
INFO:flask_app:BRICKPIINTERFACE: Starting thermal sensor thread
INFO:flask_app:LOADING THE SOUND
INFO:flask_app:ULTRASONIC: get_sensor error: Invalid sensor data
INFO:werkzeug:127.0.0.1 - - [25/Feb/2022 23:23:13] "[37mPOST /robotload HTTP/1.1[0m" 200 -
INFO:flask_app:READING CAMERA
INFO:werkzeug:127.0.0.1 - - [25/Feb/2022 23:23:13] "[37mGET /videofeed HTTP/1.1[0m" 200 -
INFO:werkzeug:127.0.0.1 - - [25/Feb/2022 23:26:39] "[37mGET /dashboard HTTP/1.1[0m" 200 -
INFO:werkzeug:127.0.0.1 - - [25/Feb/2022 23:26:41] "[37mGET /static/js/ajax_function.js HTTP/1.1[0m" 200 -
INFO:flask_app:READING CAMERA
INFO:werkzeug:127.0.0.1 - - [25/Feb/2022 23:26:43] "[37mGET /videofeed HTTP/1.1[0m" 200 -
INFO:werkzeug: * Detected change in '/home/pi/Desktop/brickpi2022/interfaces/camerainterface.py', reloading
INFO:werkzeug:127.0.0.1 - - [25/Feb/2022 23:28:12] "[37mGET /dashboard HTTP/1.1[0m" 200 -
INFO:flask_app:LOADING CAMERA
INFO:root:CAMERA INTERFACE: Started Camera Thread
INFO:flask_app:LOADING THE ROBOT
INFO:werkzeug: * Detected change in '/home/pi/Desktop/brickpi2022/interfaces/camerainterface.py', reloading
INFO:werkzeug: * Detected change in '/home/pi/Desktop/brickpi2022/interfaces/camerainterface.py', reloading
INFO:werkzeug:127.0.0.1 - - [25/Feb/2022 23:31:00] "[37mGET /dashboard HTTP/1.1[0m" 200 -
INFO:flask_app:LOADING CAMERA
INFO:root:CAMERA INTERFACE: Started Camera Thread
INFO:flask_app:LOADING THE ROBOT
INFO:werkzeug: * Detected change in '/home/pi/Desktop/brickpi2022/interfaces/camerainterface.py', reloading
INFO:werkzeug:127.0.0.1 - - [25/Feb/2022 23:32:39] "[37mGET /dashboard HTTP/1.1[0m" 200 -
INFO:flask_app:LOADING CAMERA
INFO:root:CAMERA INTERFACE: Started Camera Thread
INFO:flask_app:LOADING THE ROBOT
INFO:flask_app:BRICKPIINTERFACE: Starting thermal sensor thread
INFO:flask_app:LOADING THE SOUND
INFO:flask_app:ULTRASONIC: get_sensor error: Invalid sensor data
INFO:werkzeug:127.0.0.1 - - [25/Feb/2022 23:32:45] "[37mPOST /robotload HTTP/1.1[0m" 200 -
INFO:flask_app:ULTRASONIC: get_sensor error: Invalid sensor data
INFO:werkzeug:127.0.0.1 - - [25/Feb/2022 23:32:46] "[37mPOST /robotload HTTP/1.1[0m" 200 -
INFO:flask_app:READING CAMERA
INFO:werkzeug:127.0.0.1 - - [25/Feb/2022 23:32:46] "[37mGET /videofeed HTTP/1.1[0m" 200 -
INFO:werkzeug: * Detected change in '/home/pi/Desktop/brickpi2022/interfaces/camerainterface.py', reloading
INFO:werkzeug:127.0.0.1 - - [25/Feb/2022 23:33:24] "[37mGET /dashboard HTTP/1.1[0m" 200 -
INFO:flask_app:LOADING CAMERA
INFO:root:CAMERA INTERFACE: Started Camera Thread
INFO:flask_app:LOADING THE ROBOT
INFO:flask_app:BRICKPIINTERFACE: Starting thermal sensor thread
INFO:flask_app:LOADING THE SOUND
INFO:flask_app:ULTRASONIC: get_sensor error: Invalid sensor data
INFO:werkzeug:127.0.0.1 - - [25/Feb/2022 23:33:31] "[37mPOST /robotload HTTP/1.1[0m" 200 -
INFO:flask_app:READING CAMERA
INFO:werkzeug:127.0.0.1 - - [25/Feb/2022 23:33:31] "[37mGET /videofeed HTTP/1.1[0m" 200 -
INFO:werkzeug:127.0.0.1 - - [25/Feb/2022 23:33:56] "[37mGET /dashboard HTTP/1.1[0m" 200 -
INFO:flask_app:READING CAMERA
INFO:werkzeug:127.0.0.1 - - [25/Feb/2022 23:33:58] "[37mGET /videofeed HTTP/1.1[0m" 200 -
INFO:werkzeug: * Detected change in '/home/pi/Desktop/brickpi2022/flask_app.py', reloading
INFO:werkzeug:127.0.0.1 - - [25/Feb/2022 23:37:41] "[37mGET /dashboard HTTP/1.1[0m" 200 -
INFO:flask_app:LOADING CAMERA
INFO:root:CAMERA INTERFACE: Started Camera Thread
INFO:flask_app:LOADING THE ROBOT
INFO:flask_app:BRICKPIINTERFACE: Starting thermal sensor thread
INFO:flask_app:LOADING THE SOUND
INFO:flask_app:ULTRASONIC: get_sensor error: Invalid sensor data
INFO:werkzeug:127.0.0.1 - - [25/Feb/2022 23:37:49] "[37mPOST /robotload HTTP/1.1[0m" 200 -
INFO:flask_app:READING CAMERA
INFO:werkzeug:127.0.0.1 - - [25/Feb/2022 23:37:50] "[37mGET /videofeed HTTP/1.1[0m" 200 -
INFO:werkzeug: * Detected change in '/home/pi/Desktop/brickpi2022/flask_app.py', reloading
INFO:werkzeug:127.0.0.1 - - [25/Feb/2022 23:38:57] "[37mGET /dashboard HTTP/1.1[0m" 200 -
INFO:flask_app:LOADING CAMERA
INFO:root:CAMERA INTERFACE: Started Camera Thread
INFO:flask_app:LOADING THE ROBOT
INFO:flask_app:BRICKPIINTERFACE: Starting thermal sensor thread
INFO:flask_app:LOADING THE SOUND
INFO:flask_app:ULTRASONIC: get_sensor error: Invalid sensor data
INFO:werkzeug:127.0.0.1 - - [25/Feb/2022 23:39:05] "[37mPOST /robotload HTTP/1.1[0m" 200 -
INFO:flask_app:READING CAMERA
INFO:werkzeug:127.0.0.1 - - [25/Feb/2022 23:39:05] "[37mGET /videofeed HTTP/1.1[0m" 200 -
INFO:werkzeug:127.0.0.1 - - [25/Feb/2022 23:40:46] "[37mGET /dashboard HTTP/1.1[0m" 200 -
INFO:flask_app:READING CAMERA
INFO:werkzeug:127.0.0.1 - - [25/Feb/2022 23:40:48] "[37mGET /videofeed HTTP/1.1[0m" 200 -
INFO:werkzeug:127.0.0.1 - - [25/Feb/2022 23:41:32] "[37mGET /dashboard HTTP/1.1[0m" 200 -
INFO:flask_app:READING CAMERA
INFO:werkzeug:127.0.0.1 - - [25/Feb/2022 23:41:34] "[37mGET /videofeed HTTP/1.1[0m" 200 -
INFO:werkzeug:127.0.0.1 - - [25/Feb/2022 23:42:47] "[37mGET /dashboard HTTP/1.1[0m" 200 -
INFO:werkzeug:127.0.0.1 - - [25/Feb/2022 23:42:47] "[33mGET /favicon.ico HTTP/1.1[0m" 404 -
INFO:flask_app:LOADING CAMERA
INFO:root:CAMERA INTERFACE: Started Camera Thread
INFO:flask_app:LOADING THE ROBOT
INFO:flask_app:BRICKPIINTERFACE: Starting thermal sensor thread
INFO:flask_app:LOADING THE SOUND
INFO:flask_app:ULTRASONIC: get_sensor error: Invalid sensor data
INFO:werkzeug:127.0.0.1 - - [25/Feb/2022 23:42:54] "[37mPOST /robotload HTTP/1.1[0m" 200 -
INFO:flask_app:READING CAMERA
INFO:werkzeug:127.0.0.1 - - [25/Feb/2022 23:42:54] "[37mGET /videofeed HTTP/1.1[0m" 200 -
INFO:werkzeug:127.0.0.1 - - [25/Feb/2022 23:43:54] "[33mGET /dashboard/missions HTTP/1.1[0m" 404 -
INFO:werkzeug: * Detected change in '/home/pi/Desktop/brickpi2022/flask_app.py', reloading
INFO:werkzeug: * Restarting with stat
INFO:werkzeug:127.0.0.1 - - [25/Feb/2022 23:44:21] "[37mGET /missions HTTP/1.1[0m" 200 -
INFO:werkzeug:127.0.0.1 - - [25/Feb/2022 23:44:26] "[33mGET /missions/history HTTP/1.1[0m" 404 -
INFO:werkzeug:127.0.0.1 - - [25/Feb/2022 23:44:33] "[37mGET /missions-history HTTP/1.1[0m" 200 -
INFO:werkzeug:127.0.0.1 - - [25/Feb/2022 23:44:33] "[33mGET /static/JavaScript/mission_data.js HTTP/1.1[0m" 404 -
INFO:werkzeug:127.0.0.1 - - [25/Feb/2022 23:44:34] "[33mGET /static/JavaScript/mission_data.js HTTP/1.1[0m" 404 -
INFO:werkzeug:127.0.0.1 - - [25/Feb/2022 23:44:34] "[33mGET /static/JavaScript/mission_data.js HTTP/1.1[0m" 404 -
INFO:werkzeug: * Detected change in '/home/pi/Desktop/brickpi2022/flask_app.py', reloading
INFO:werkzeug: * Restarting with stat
INFO:werkzeug:127.0.0.1 - - [25/Feb/2022 23:46:11] "[37mGET /missions/history HTTP/1.1[0m" 200 -
INFO:werkzeug:127.0.0.1 - - [25/Feb/2022 23:46:11] "[33mGET /missions/static/js/ajax_function.js HTTP/1.1[0m" 404 -
INFO:werkzeug:127.0.0.1 - - [25/Feb/2022 23:46:11] "[37mGET /static/js/mission_data.js HTTP/1.1[0m" 200 -
INFO:werkzeug:127.0.0.1 - - [25/Feb/2022 23:46:11] "[33mGET /missions/static/js/ajax_function.js HTTP/1.1[0m" 404 -
INFO:werkzeug:127.0.0.1 - - [25/Feb/2022 23:46:48] "[37mGET /missions/history HTTP/1.1[0m" 200 -
INFO:werkzeug:127.0.0.1 - - [25/Feb/2022 23:46:48] "[33mGET /missions/static/js/ajax_function.js HTTP/1.1[0m" 404 -
